2024-12-21 13:12:05,898 INFO    StreamThr :3783459 [internal.py:wandb_internal():86] W&B internal server running at pid: 3783459, started at: 2024-12-21 13:12:05.897069
2024-12-21 13:12:05,901 DEBUG   HandlerThread:3783459 [handler.py:handle_request():146] handle_request: status
2024-12-21 13:12:05,910 INFO    WriterThread:3783459 [datastore.py:open_for_write():87] open: /home/wangc/now/pure/ALinAirway/wandb/run-20241221_131205-ouk2oc2k/run-ouk2oc2k.wandb
2024-12-21 13:12:05,911 DEBUG   SenderThread:3783459 [sender.py:send():379] send: header
2024-12-21 13:12:06,068 DEBUG   SenderThread:3783459 [sender.py:send():379] send: run
2024-12-21 13:12:11,070 DEBUG   HandlerThread:3783459 [handler.py:handle_request():146] handle_request: keepalive
2024-12-21 13:12:16,071 DEBUG   HandlerThread:3783459 [handler.py:handle_request():146] handle_request: keepalive
2024-12-21 13:12:21,073 DEBUG   HandlerThread:3783459 [handler.py:handle_request():146] handle_request: keepalive
2024-12-21 13:12:26,074 DEBUG   HandlerThread:3783459 [handler.py:handle_request():146] handle_request: keepalive
2024-12-21 13:12:31,076 DEBUG   HandlerThread:3783459 [handler.py:handle_request():146] handle_request: keepalive
2024-12-21 13:12:36,078 DEBUG   HandlerThread:3783459 [handler.py:handle_request():146] handle_request: keepalive
2024-12-21 13:12:41,080 DEBUG   HandlerThread:3783459 [handler.py:handle_request():146] handle_request: keepalive
2024-12-21 13:12:46,081 DEBUG   HandlerThread:3783459 [handler.py:handle_request():146] handle_request: keepalive
2024-12-21 13:12:51,083 DEBUG   HandlerThread:3783459 [handler.py:handle_request():146] handle_request: keepalive
2024-12-21 13:12:56,085 DEBUG   HandlerThread:3783459 [handler.py:handle_request():146] handle_request: keepalive
2024-12-21 13:13:01,087 DEBUG   HandlerThread:3783459 [handler.py:handle_request():146] handle_request: keepalive
2024-12-21 13:13:06,089 DEBUG   HandlerThread:3783459 [handler.py:handle_request():146] handle_request: keepalive
2024-12-21 13:13:10,108 INFO    SenderThread:3783459 [retry.py:__call__():172] Retry attempt failed:
Traceback (most recent call last):
  File "/home/wangc/anaconda3/envs/test1/lib/python3.8/site-packages/urllib3/connection.py", line 174, in _new_conn
    conn = connection.create_connection(
  File "/home/wangc/anaconda3/envs/test1/lib/python3.8/site-packages/urllib3/util/connection.py", line 95, in create_connection
    raise err
  File "/home/wangc/anaconda3/envs/test1/lib/python3.8/site-packages/urllib3/util/connection.py", line 85, in create_connection
    sock.connect(sa)
socket.timeout: timed out

During handling of the above exception, another exception occurred:

Traceback (most recent call last):
  File "/home/wangc/anaconda3/envs/test1/lib/python3.8/site-packages/urllib3/connectionpool.py", line 703, in urlopen
    httplib_response = self._make_request(
  File "/home/wangc/anaconda3/envs/test1/lib/python3.8/site-packages/urllib3/connectionpool.py", line 386, in _make_request
    self._validate_conn(conn)
  File "/home/wangc/anaconda3/envs/test1/lib/python3.8/site-packages/urllib3/connectionpool.py", line 1042, in _validate_conn
    conn.connect()
  File "/home/wangc/anaconda3/envs/test1/lib/python3.8/site-packages/urllib3/connection.py", line 358, in connect
    self.sock = conn = self._new_conn()
  File "/home/wangc/anaconda3/envs/test1/lib/python3.8/site-packages/urllib3/connection.py", line 179, in _new_conn
    raise ConnectTimeoutError(
urllib3.exceptions.ConnectTimeoutError: (<urllib3.connection.HTTPSConnection object at 0x7f6796372670>, 'Connection to api.wandb.ai timed out. (connect timeout=20)')

During handling of the above exception, another exception occurred:

Traceback (most recent call last):
  File "/home/wangc/anaconda3/envs/test1/lib/python3.8/site-packages/requests/adapters.py", line 489, in send
    resp = conn.urlopen(
  File "/home/wangc/anaconda3/envs/test1/lib/python3.8/site-packages/urllib3/connectionpool.py", line 787, in urlopen
    retries = retries.increment(
  File "/home/wangc/anaconda3/envs/test1/lib/python3.8/site-packages/urllib3/util/retry.py", line 592, in increment
    raise MaxRetryError(_pool, url, error or ResponseError(cause))
urllib3.exceptions.MaxRetryError: HTTPSConnectionPool(host='api.wandb.ai', port=443): Max retries exceeded with url: /graphql (Caused by ConnectTimeoutError(<urllib3.connection.HTTPSConnection object at 0x7f6796372670>, 'Connection to api.wandb.ai timed out. (connect timeout=20)'))

During handling of the above exception, another exception occurred:

Traceback (most recent call last):
  File "/home/wangc/anaconda3/envs/test1/lib/python3.8/site-packages/wandb/sdk/lib/retry.py", line 131, in __call__
    result = self._call_fn(*args, **kwargs)
  File "/home/wangc/anaconda3/envs/test1/lib/python3.8/site-packages/wandb/sdk/internal/internal_api.py", line 369, in execute
    return self.client.execute(*args, **kwargs)  # type: ignore
  File "/home/wangc/anaconda3/envs/test1/lib/python3.8/site-packages/wandb/vendor/gql-0.2.0/wandb_gql/client.py", line 52, in execute
    result = self._get_result(document, *args, **kwargs)
  File "/home/wangc/anaconda3/envs/test1/lib/python3.8/site-packages/wandb/vendor/gql-0.2.0/wandb_gql/client.py", line 60, in _get_result
    return self.transport.execute(document, *args, **kwargs)
  File "/home/wangc/anaconda3/envs/test1/lib/python3.8/site-packages/wandb/sdk/lib/gql_request.py", line 58, in execute
    request = self.session.post(self.url, **post_args)
  File "/home/wangc/anaconda3/envs/test1/lib/python3.8/site-packages/requests/sessions.py", line 635, in post
    return self.request("POST", url, data=data, json=json, **kwargs)
  File "/home/wangc/anaconda3/envs/test1/lib/python3.8/site-packages/requests/sessions.py", line 587, in request
    resp = self.send(prep, **send_kwargs)
  File "/home/wangc/anaconda3/envs/test1/lib/python3.8/site-packages/requests/sessions.py", line 701, in send
    r = adapter.send(request, **kwargs)
  File "/home/wangc/anaconda3/envs/test1/lib/python3.8/site-packages/requests/adapters.py", line 553, in send
    raise ConnectTimeout(e, request=request)
requests.exceptions.ConnectTimeout: HTTPSConnectionPool(host='api.wandb.ai', port=443): Max retries exceeded with url: /graphql (Caused by ConnectTimeoutError(<urllib3.connection.HTTPSConnection object at 0x7f6796372670>, 'Connection to api.wandb.ai timed out. (connect timeout=20)'))
2024-12-21 13:13:11,090 DEBUG   HandlerThread:3783459 [handler.py:handle_request():146] handle_request: keepalive
2024-12-21 13:13:16,092 DEBUG   HandlerThread:3783459 [handler.py:handle_request():146] handle_request: keepalive
2024-12-21 13:13:21,094 DEBUG   HandlerThread:3783459 [handler.py:handle_request():146] handle_request: keepalive
2024-12-21 13:13:26,096 DEBUG   HandlerThread:3783459 [handler.py:handle_request():146] handle_request: keepalive
2024-12-21 13:13:31,097 DEBUG   HandlerThread:3783459 [handler.py:handle_request():146] handle_request: keepalive
2024-12-21 13:13:36,099 DEBUG   HandlerThread:3783459 [handler.py:handle_request():146] handle_request: cancel
2024-12-21 13:13:36,100 DEBUG   HandlerThread:3783459 [handler.py:handle_request():146] handle_request: cancel
2024-12-21 13:13:36,101 DEBUG   SenderThread:3783459 [sender.py:send():388] Record cancelled: run
2024-12-21 13:13:36,101 DEBUG   HandlerThread:3783459 [handler.py:handle_request():146] handle_request: status_report
2024-12-21 13:13:36,952 DEBUG   HandlerThread:3783459 [handler.py:handle_request():146] handle_request: shutdown
2024-12-21 13:13:36,953 INFO    HandlerThread:3783459 [handler.py:finish():866] shutting down handler
2024-12-21 13:13:37,101 INFO    SenderThread:3783459 [sender.py:finish():1546] shutting down sender
2024-12-21 13:13:37,102 INFO    WriterThread:3783459 [datastore.py:close():296] close: /home/wangc/now/pure/ALinAirway/wandb/run-20241221_131205-ouk2oc2k/run-ouk2oc2k.wandb
