2024-12-21 13:17:23,277 INFO    StreamThr :4023993 [internal.py:wandb_internal():86] W&B internal server running at pid: 4023993, started at: 2024-12-21 13:17:23.275368
2024-12-21 13:17:23,280 DEBUG   HandlerThread:4023993 [handler.py:handle_request():146] handle_request: status
2024-12-21 13:17:23,283 INFO    WriterThread:4023993 [datastore.py:open_for_write():87] open: /home/wangc/now/pure/ALinAirway/wandb/run-20241221_131723-9lwe4ti5/run-9lwe4ti5.wandb
2024-12-21 13:17:23,286 DEBUG   SenderThread:4023993 [sender.py:send():379] send: header
2024-12-21 13:17:23,430 DEBUG   SenderThread:4023993 [sender.py:send():379] send: run
2024-12-21 13:17:28,431 DEBUG   HandlerThread:4023993 [handler.py:handle_request():146] handle_request: keepalive
2024-12-21 13:17:33,433 DEBUG   HandlerThread:4023993 [handler.py:handle_request():146] handle_request: keepalive
2024-12-21 13:17:38,435 DEBUG   HandlerThread:4023993 [handler.py:handle_request():146] handle_request: keepalive
2024-12-21 13:17:43,436 DEBUG   HandlerThread:4023993 [handler.py:handle_request():146] handle_request: keepalive
2024-12-21 13:17:48,438 DEBUG   HandlerThread:4023993 [handler.py:handle_request():146] handle_request: keepalive
2024-12-21 13:17:53,440 DEBUG   HandlerThread:4023993 [handler.py:handle_request():146] handle_request: keepalive
2024-12-21 13:17:58,442 DEBUG   HandlerThread:4023993 [handler.py:handle_request():146] handle_request: keepalive
2024-12-21 13:18:03,444 DEBUG   HandlerThread:4023993 [handler.py:handle_request():146] handle_request: keepalive
2024-12-21 13:18:08,446 DEBUG   HandlerThread:4023993 [handler.py:handle_request():146] handle_request: keepalive
2024-12-21 13:18:13,447 DEBUG   HandlerThread:4023993 [handler.py:handle_request():146] handle_request: keepalive
2024-12-21 13:18:16,081 INFO    SenderThread:4023993 [dir_watcher.py:__init__():211] watching files in: /home/wangc/now/pure/ALinAirway/wandb/run-20241221_131723-9lwe4ti5/files
2024-12-21 13:18:16,081 INFO    SenderThread:4023993 [sender.py:_start_run_threads():1124] run started: 9lwe4ti5 with start time 1734787043.274653
2024-12-21 13:18:16,081 DEBUG   HandlerThread:4023993 [handler.py:handle_request():146] handle_request: status_report
2024-12-21 13:18:16,107 DEBUG   HandlerThread:4023993 [handler.py:handle_request():146] handle_request: check_version
2024-12-21 13:18:16,108 DEBUG   SenderThread:4023993 [sender.py:send_request():406] send_request: check_version
2024-12-21 13:18:17,335 DEBUG   HandlerThread:4023993 [handler.py:handle_request():146] handle_request: run_start
2024-12-21 13:18:17,367 DEBUG   HandlerThread:4023993 [system_info.py:__init__():26] System info init
2024-12-21 13:18:17,367 DEBUG   HandlerThread:4023993 [system_info.py:__init__():41] System info init done
2024-12-21 13:18:17,367 INFO    HandlerThread:4023993 [system_monitor.py:start():194] Starting system monitor
2024-12-21 13:18:17,367 INFO    SystemMonitor:4023993 [system_monitor.py:_start():158] Starting system asset monitoring threads
2024-12-21 13:18:17,367 INFO    HandlerThread:4023993 [system_monitor.py:probe():214] Collecting system info
2024-12-21 13:18:17,368 INFO    SystemMonitor:4023993 [interfaces.py:start():190] Started cpu monitoring
2024-12-21 13:18:17,370 INFO    SystemMonitor:4023993 [interfaces.py:start():190] Started disk monitoring
2024-12-21 13:18:17,371 INFO    SystemMonitor:4023993 [interfaces.py:start():190] Started gpu monitoring
2024-12-21 13:18:17,372 INFO    SystemMonitor:4023993 [interfaces.py:start():190] Started memory monitoring
2024-12-21 13:18:17,374 INFO    SystemMonitor:4023993 [interfaces.py:start():190] Started network monitoring
2024-12-21 13:18:17,437 DEBUG   HandlerThread:4023993 [system_info.py:probe():150] Probing system
2024-12-21 13:18:17,450 DEBUG   HandlerThread:4023993 [system_info.py:_probe_git():135] Probing git
2024-12-21 13:18:17,475 DEBUG   HandlerThread:4023993 [system_info.py:_probe_git():143] Probing git done
2024-12-21 13:18:17,476 DEBUG   HandlerThread:4023993 [system_info.py:probe():198] Probing system done
2024-12-21 13:18:17,476 DEBUG   HandlerThread:4023993 [system_monitor.py:probe():223] {'os': 'Linux-5.4.0-200-generic-x86_64-with-glibc2.17', 'python': '3.8.20', 'heartbeatAt': '2024-12-21T13:18:17.437951', 'startedAt': '2024-12-21T13:17:23.262214', 'docker': None, 'cuda': None, 'args': ('--use_gpu', 'cuda:1', '--save_name', 'num40_kmeans_no_init_cluster_3_embedding_3_1221_1357', '--data_info_path', '../saved_objs/for_128_objs/training_info_1218/kmeans_no_init_cluster_3_embedding_3_test_1218_1019.pkl_num0.4.pkl', '--model', 'navi_airway'), 'state': 'running', 'program': 'train_green_t.py', 'codePathLocal': 'train_green_t.py', 'codePath': 'train_green_t.py', 'git': {'remote': 'git@github.com:chenzier/ALinAirway.git', 'commit': 'a8f9cae41d5570b481a95037ed293e010e73f4cf'}, 'email': '783208746@qq.com', 'root': '/home/wangc/now/pure/ALinAirway', 'host': 'dbcloud', 'username': 'wangc', 'executable': '/home/wangc/anaconda3/envs/test1/bin/python', 'cpu_count': 40, 'cpu_count_logical': 80, 'cpu_freq': {'current': 1.5973, 'min': 1000.0, 'max': 3000.0}, 'cpu_freq_per_core': [{'current': 2.799, 'min': 1000.0, 'max': 3000.0}, {'current': 1.731, 'min': 1000.0, 'max': 3000.0}, {'current': 1.947, 'min': 1000.0, 'max': 3000.0}, {'current': 2.468, 'min': 1000.0, 'max': 3000.0}, {'current': 1.0, 'min': 1000.0, 'max': 3000.0}, {'current': 0.999, 'min': 1000.0, 'max': 3000.0}, {'current': 1.0, 'min': 1000.0, 'max': 3000.0}, {'current': 1.0, 'min': 1000.0, 'max': 3000.0}, {'current': 2.8, 'min': 1000.0, 'max': 3000.0}, {'current': 2.8, 'min': 1000.0, 'max': 3000.0}, {'current': 1.0, 'min': 1000.0, 'max': 3000.0}, {'current': 2.8, 'min': 1000.0, 'max': 3000.0}, {'current': 1.0, 'min': 1000.0, 'max': 3000.0}, {'current': 1.001, 'min': 1000.0, 'max': 3000.0}, {'current': 1.0, 'min': 1000.0, 'max': 3000.0}, {'current': 1.0, 'min': 1000.0, 'max': 3000.0}, {'current': 1.038, 'min': 1000.0, 'max': 3000.0}, {'current': 1.0, 'min': 1000.0, 'max': 3000.0}, {'current': 1.0, 'min': 1000.0, 'max': 3000.0}, {'current': 2.748, 'min': 1000.0, 'max': 3000.0}, {'current': 2.324, 'min': 1000.0, 'max': 3000.0}, {'current': 1.233, 'min': 1000.0, 'max': 3000.0}, {'current': 1.0, 'min': 1000.0, 'max': 3000.0}, {'current': 1.0, 'min': 1000.0, 'max': 3000.0}, {'current': 1.0, 'min': 1000.0, 'max': 3000.0}, {'current': 1.0, 'min': 1000.0, 'max': 3000.0}, {'current': 2.799, 'min': 1000.0, 'max': 3000.0}, {'current': 2.799, 'min': 1000.0, 'max': 3000.0}, {'current': 1.0, 'min': 1000.0, 'max': 3000.0}, {'current': 1.0, 'min': 1000.0, 'max': 3000.0}, {'current': 1.017, 'min': 1000.0, 'max': 3000.0}, {'current': 2.282, 'min': 1000.0, 'max': 3000.0}, {'current': 1.0, 'min': 1000.0, 'max': 3000.0}, {'current': 1.0, 'min': 1000.0, 'max': 3000.0}, {'current': 1.0, 'min': 1000.0, 'max': 3000.0}, {'current': 2.228, 'min': 1000.0, 'max': 3000.0}, {'current': 1.0, 'min': 1000.0, 'max': 3000.0}, {'current': 1.18, 'min': 1000.0, 'max': 3000.0}, {'current': 1.0, 'min': 1000.0, 'max': 3000.0}, {'current': 1.0, 'min': 1000.0, 'max': 3000.0}, {'current': 2.8, 'min': 1000.0, 'max': 3000.0}, {'current': 1.844, 'min': 1000.0, 'max': 3000.0}, {'current': 1.978, 'min': 1000.0, 'max': 3000.0}, {'current': 2.679, 'min': 1000.0, 'max': 3000.0}, {'current': 1.0, 'min': 1000.0, 'max': 3000.0}, {'current': 1.0, 'min': 1000.0, 'max': 3000.0}, {'current': 1.0, 'min': 1000.0, 'max': 3000.0}, {'current': 1.0, 'min': 1000.0, 'max': 3000.0}, {'current': 2.798, 'min': 1000.0, 'max': 3000.0}, {'current': 2.799, 'min': 1000.0, 'max': 3000.0}, {'current': 1.0, 'min': 1000.0, 'max': 3000.0}, {'current': 2.8, 'min': 1000.0, 'max': 3000.0}, {'current': 1.0, 'min': 1000.0, 'max': 3000.0}, {'current': 1.0, 'min': 1000.0, 'max': 3000.0}, {'current': 1.0, 'min': 1000.0, 'max': 3000.0}, {'current': 1.001, 'min': 1000.0, 'max': 3000.0}, {'current': 1.025, 'min': 1000.0, 'max': 3000.0}, {'current': 1.0, 'min': 1000.0, 'max': 3000.0}, {'current': 1.001, 'min': 1000.0, 'max': 3000.0}, {'current': 2.796, 'min': 1000.0, 'max': 3000.0}, {'current': 2.549, 'min': 1000.0, 'max': 3000.0}, {'current': 1.007, 'min': 1000.0, 'max': 3000.0}, {'current': 1.0, 'min': 1000.0, 'max': 3000.0}, {'current': 1.0, 'min': 1000.0, 'max': 3000.0}, {'current': 1.0, 'min': 1000.0, 'max': 3000.0}, {'current': 1.0, 'min': 1000.0, 'max': 3000.0}, {'current': 2.799, 'min': 1000.0, 'max': 3000.0}, {'current': 2.799, 'min': 1000.0, 'max': 3000.0}, {'current': 1.0, 'min': 1000.0, 'max': 3000.0}, {'current': 1.0, 'min': 1000.0, 'max': 3000.0}, {'current': 1.006, 'min': 1000.0, 'max': 3000.0}, {'current': 2.51, 'min': 1000.0, 'max': 3000.0}, {'current': 1.0, 'min': 1000.0, 'max': 3000.0}, {'current': 1.0, 'min': 1000.0, 'max': 3000.0}, {'current': 1.0, 'min': 1000.0, 'max': 3000.0}, {'current': 2.26, 'min': 1000.0, 'max': 3000.0}, {'current': 1.0, 'min': 1000.0, 'max': 3000.0}, {'current': 1.192, 'min': 1000.0, 'max': 3000.0}, {'current': 1.0, 'min': 1000.0, 'max': 3000.0}, {'current': 1.0, 'min': 1000.0, 'max': 3000.0}], 'disk': {'/': {'total': 457.37662506103516, 'used': 313.6309814453125}}, 'gpu': 'NVIDIA GeForce RTX 3090', 'gpu_count': 8, 'gpu_devices': [{'name': 'NVIDIA GeForce RTX 3090', 'memory_total': 25769803776}, {'name': 'NVIDIA GeForce RTX 3090', 'memory_total': 25769803776}, {'name': 'NVIDIA GeForce RTX 3090', 'memory_total': 25769803776}, {'name': 'NVIDIA GeForce RTX 3090', 'memory_total': 25769803776}, {'name': 'NVIDIA GeForce RTX 3090', 'memory_total': 25769803776}, {'name': 'NVIDIA GeForce RTX 3090', 'memory_total': 25769803776}, {'name': 'NVIDIA GeForce RTX 3090', 'memory_total': 25769803776}, {'name': 'NVIDIA GeForce RTX 3090', 'memory_total': 25769803776}], 'memory': {'total': 251.50729370117188}}
2024-12-21 13:18:17,477 INFO    HandlerThread:4023993 [system_monitor.py:probe():224] Finished collecting system info
2024-12-21 13:18:17,477 INFO    HandlerThread:4023993 [system_monitor.py:probe():227] Publishing system info
2024-12-21 13:18:17,477 DEBUG   HandlerThread:4023993 [system_info.py:_save_conda():207] Saving list of conda packages installed into the current environment
2024-12-21 13:18:18,087 INFO    Thread-12 :4023993 [dir_watcher.py:_on_file_created():271] file/dir created: /home/wangc/now/pure/ALinAirway/wandb/run-20241221_131723-9lwe4ti5/files/conda-environment.yaml
2024-12-21 13:18:20,810 DEBUG   HandlerThread:4023993 [system_info.py:_save_conda():222] Saving conda packages done
2024-12-21 13:18:20,813 INFO    HandlerThread:4023993 [system_monitor.py:probe():229] Finished publishing system info
2024-12-21 13:18:20,819 DEBUG   SenderThread:4023993 [sender.py:send():379] send: files
2024-12-21 13:18:20,820 INFO    SenderThread:4023993 [sender.py:_save_file():1390] saving file wandb-metadata.json with policy now
2024-12-21 13:18:21,042 DEBUG   HandlerThread:4023993 [handler.py:handle_request():146] handle_request: python_packages
2024-12-21 13:18:21,043 DEBUG   SenderThread:4023993 [sender.py:send_request():406] send_request: python_packages
2024-12-21 13:18:21,044 DEBUG   HandlerThread:4023993 [handler.py:handle_request():146] handle_request: stop_status
2024-12-21 13:18:21,044 DEBUG   SenderThread:4023993 [sender.py:send_request():406] send_request: stop_status
2024-12-21 13:18:21,049 DEBUG   HandlerThread:4023993 [handler.py:handle_request():146] handle_request: internal_messages
2024-12-21 13:18:21,084 INFO    Thread-12 :4023993 [dir_watcher.py:_on_file_modified():288] file/dir modified: /home/wangc/now/pure/ALinAirway/wandb/run-20241221_131723-9lwe4ti5/files/conda-environment.yaml
2024-12-21 13:18:21,085 INFO    Thread-12 :4023993 [dir_watcher.py:_on_file_created():271] file/dir created: /home/wangc/now/pure/ALinAirway/wandb/run-20241221_131723-9lwe4ti5/files/requirements.txt
2024-12-21 13:18:21,085 INFO    Thread-12 :4023993 [dir_watcher.py:_on_file_created():271] file/dir created: /home/wangc/now/pure/ALinAirway/wandb/run-20241221_131723-9lwe4ti5/files/wandb-metadata.json
2024-12-21 13:18:27,046 DEBUG   HandlerThread:4023993 [handler.py:handle_request():146] handle_request: keepalive
2024-12-21 13:18:32,047 DEBUG   HandlerThread:4023993 [handler.py:handle_request():146] handle_request: keepalive
2024-12-21 13:18:36,045 DEBUG   HandlerThread:4023993 [handler.py:handle_request():146] handle_request: internal_messages
2024-12-21 13:18:41,049 DEBUG   HandlerThread:4023993 [handler.py:handle_request():146] handle_request: keepalive
2024-12-21 13:18:46,050 DEBUG   HandlerThread:4023993 [handler.py:handle_request():146] handle_request: keepalive
2024-12-21 13:18:51,046 DEBUG   HandlerThread:4023993 [handler.py:handle_request():146] handle_request: internal_messages
2024-12-21 13:18:56,060 DEBUG   HandlerThread:4023993 [handler.py:handle_request():146] handle_request: keepalive
2024-12-21 13:18:59,426 DEBUG   HandlerThread:4023993 [handler.py:handle_request():146] handle_request: poll_exit
2024-12-21 13:19:02,124 INFO    wandb-upload_0:4023993 [retry.py:__call__():172] Retry attempt failed:
Traceback (most recent call last):
  File "/home/wangc/anaconda3/envs/test1/lib/python3.8/site-packages/urllib3/connection.py", line 174, in _new_conn
    conn = connection.create_connection(
  File "/home/wangc/anaconda3/envs/test1/lib/python3.8/site-packages/urllib3/util/connection.py", line 95, in create_connection
    raise err
  File "/home/wangc/anaconda3/envs/test1/lib/python3.8/site-packages/urllib3/util/connection.py", line 85, in create_connection
    sock.connect(sa)
socket.timeout: timed out

During handling of the above exception, another exception occurred:

Traceback (most recent call last):
  File "/home/wangc/anaconda3/envs/test1/lib/python3.8/site-packages/urllib3/connectionpool.py", line 703, in urlopen
    httplib_response = self._make_request(
  File "/home/wangc/anaconda3/envs/test1/lib/python3.8/site-packages/urllib3/connectionpool.py", line 386, in _make_request
    self._validate_conn(conn)
  File "/home/wangc/anaconda3/envs/test1/lib/python3.8/site-packages/urllib3/connectionpool.py", line 1042, in _validate_conn
    conn.connect()
  File "/home/wangc/anaconda3/envs/test1/lib/python3.8/site-packages/urllib3/connection.py", line 358, in connect
    self.sock = conn = self._new_conn()
  File "/home/wangc/anaconda3/envs/test1/lib/python3.8/site-packages/urllib3/connection.py", line 179, in _new_conn
    raise ConnectTimeoutError(
urllib3.exceptions.ConnectTimeoutError: (<urllib3.connection.HTTPSConnection object at 0x7fa25d2fa850>, 'Connection to api.wandb.ai timed out. (connect timeout=20)')

During handling of the above exception, another exception occurred:

Traceback (most recent call last):
  File "/home/wangc/anaconda3/envs/test1/lib/python3.8/site-packages/requests/adapters.py", line 489, in send
    resp = conn.urlopen(
  File "/home/wangc/anaconda3/envs/test1/lib/python3.8/site-packages/urllib3/connectionpool.py", line 787, in urlopen
    retries = retries.increment(
  File "/home/wangc/anaconda3/envs/test1/lib/python3.8/site-packages/urllib3/util/retry.py", line 592, in increment
    raise MaxRetryError(_pool, url, error or ResponseError(cause))
urllib3.exceptions.MaxRetryError: HTTPSConnectionPool(host='api.wandb.ai', port=443): Max retries exceeded with url: /graphql (Caused by ConnectTimeoutError(<urllib3.connection.HTTPSConnection object at 0x7fa25d2fa850>, 'Connection to api.wandb.ai timed out. (connect timeout=20)'))

During handling of the above exception, another exception occurred:

Traceback (most recent call last):
  File "/home/wangc/anaconda3/envs/test1/lib/python3.8/site-packages/wandb/sdk/lib/retry.py", line 131, in __call__
    result = self._call_fn(*args, **kwargs)
  File "/home/wangc/anaconda3/envs/test1/lib/python3.8/site-packages/wandb/sdk/internal/internal_api.py", line 369, in execute
    return self.client.execute(*args, **kwargs)  # type: ignore
  File "/home/wangc/anaconda3/envs/test1/lib/python3.8/site-packages/wandb/vendor/gql-0.2.0/wandb_gql/client.py", line 52, in execute
    result = self._get_result(document, *args, **kwargs)
  File "/home/wangc/anaconda3/envs/test1/lib/python3.8/site-packages/wandb/vendor/gql-0.2.0/wandb_gql/client.py", line 60, in _get_result
    return self.transport.execute(document, *args, **kwargs)
  File "/home/wangc/anaconda3/envs/test1/lib/python3.8/site-packages/wandb/sdk/lib/gql_request.py", line 58, in execute
    request = self.session.post(self.url, **post_args)
  File "/home/wangc/anaconda3/envs/test1/lib/python3.8/site-packages/requests/sessions.py", line 635, in post
    return self.request("POST", url, data=data, json=json, **kwargs)
  File "/home/wangc/anaconda3/envs/test1/lib/python3.8/site-packages/requests/sessions.py", line 587, in request
    resp = self.send(prep, **send_kwargs)
  File "/home/wangc/anaconda3/envs/test1/lib/python3.8/site-packages/requests/sessions.py", line 701, in send
    r = adapter.send(request, **kwargs)
  File "/home/wangc/anaconda3/envs/test1/lib/python3.8/site-packages/requests/adapters.py", line 553, in send
    raise ConnectTimeout(e, request=request)
requests.exceptions.ConnectTimeout: HTTPSConnectionPool(host='api.wandb.ai', port=443): Max retries exceeded with url: /graphql (Caused by ConnectTimeoutError(<urllib3.connection.HTTPSConnection object at 0x7fa25d2fa850>, 'Connection to api.wandb.ai timed out. (connect timeout=20)'))
2024-12-21 13:19:02,708 INFO    SenderThread:4023993 [retry.py:__call__():172] Retry attempt failed:
Traceback (most recent call last):
  File "/home/wangc/anaconda3/envs/test1/lib/python3.8/site-packages/urllib3/connection.py", line 174, in _new_conn
    conn = connection.create_connection(
  File "/home/wangc/anaconda3/envs/test1/lib/python3.8/site-packages/urllib3/util/connection.py", line 95, in create_connection
    raise err
  File "/home/wangc/anaconda3/envs/test1/lib/python3.8/site-packages/urllib3/util/connection.py", line 85, in create_connection
    sock.connect(sa)
socket.timeout: timed out

During handling of the above exception, another exception occurred:

Traceback (most recent call last):
  File "/home/wangc/anaconda3/envs/test1/lib/python3.8/site-packages/urllib3/connectionpool.py", line 703, in urlopen
    httplib_response = self._make_request(
  File "/home/wangc/anaconda3/envs/test1/lib/python3.8/site-packages/urllib3/connectionpool.py", line 386, in _make_request
    self._validate_conn(conn)
  File "/home/wangc/anaconda3/envs/test1/lib/python3.8/site-packages/urllib3/connectionpool.py", line 1042, in _validate_conn
    conn.connect()
  File "/home/wangc/anaconda3/envs/test1/lib/python3.8/site-packages/urllib3/connection.py", line 358, in connect
    self.sock = conn = self._new_conn()
  File "/home/wangc/anaconda3/envs/test1/lib/python3.8/site-packages/urllib3/connection.py", line 179, in _new_conn
    raise ConnectTimeoutError(
urllib3.exceptions.ConnectTimeoutError: (<urllib3.connection.HTTPSConnection object at 0x7fa25d1892b0>, 'Connection to api.wandb.ai timed out. (connect timeout=20)')

During handling of the above exception, another exception occurred:

Traceback (most recent call last):
  File "/home/wangc/anaconda3/envs/test1/lib/python3.8/site-packages/requests/adapters.py", line 489, in send
    resp = conn.urlopen(
  File "/home/wangc/anaconda3/envs/test1/lib/python3.8/site-packages/urllib3/connectionpool.py", line 787, in urlopen
    retries = retries.increment(
  File "/home/wangc/anaconda3/envs/test1/lib/python3.8/site-packages/urllib3/util/retry.py", line 592, in increment
    raise MaxRetryError(_pool, url, error or ResponseError(cause))
urllib3.exceptions.MaxRetryError: HTTPSConnectionPool(host='api.wandb.ai', port=443): Max retries exceeded with url: /graphql (Caused by ConnectTimeoutError(<urllib3.connection.HTTPSConnection object at 0x7fa25d1892b0>, 'Connection to api.wandb.ai timed out. (connect timeout=20)'))

During handling of the above exception, another exception occurred:

Traceback (most recent call last):
  File "/home/wangc/anaconda3/envs/test1/lib/python3.8/site-packages/wandb/sdk/lib/retry.py", line 131, in __call__
    result = self._call_fn(*args, **kwargs)
  File "/home/wangc/anaconda3/envs/test1/lib/python3.8/site-packages/wandb/sdk/internal/internal_api.py", line 369, in execute
    return self.client.execute(*args, **kwargs)  # type: ignore
  File "/home/wangc/anaconda3/envs/test1/lib/python3.8/site-packages/wandb/vendor/gql-0.2.0/wandb_gql/client.py", line 52, in execute
    result = self._get_result(document, *args, **kwargs)
  File "/home/wangc/anaconda3/envs/test1/lib/python3.8/site-packages/wandb/vendor/gql-0.2.0/wandb_gql/client.py", line 60, in _get_result
    return self.transport.execute(document, *args, **kwargs)
  File "/home/wangc/anaconda3/envs/test1/lib/python3.8/site-packages/wandb/sdk/lib/gql_request.py", line 58, in execute
    request = self.session.post(self.url, **post_args)
  File "/home/wangc/anaconda3/envs/test1/lib/python3.8/site-packages/requests/sessions.py", line 635, in post
    return self.request("POST", url, data=data, json=json, **kwargs)
  File "/home/wangc/anaconda3/envs/test1/lib/python3.8/site-packages/requests/sessions.py", line 587, in request
    resp = self.send(prep, **send_kwargs)
  File "/home/wangc/anaconda3/envs/test1/lib/python3.8/site-packages/requests/sessions.py", line 701, in send
    r = adapter.send(request, **kwargs)
  File "/home/wangc/anaconda3/envs/test1/lib/python3.8/site-packages/requests/adapters.py", line 553, in send
    raise ConnectTimeout(e, request=request)
requests.exceptions.ConnectTimeout: HTTPSConnectionPool(host='api.wandb.ai', port=443): Max retries exceeded with url: /graphql (Caused by ConnectTimeoutError(<urllib3.connection.HTTPSConnection object at 0x7fa25d1892b0>, 'Connection to api.wandb.ai timed out. (connect timeout=20)'))
2024-12-21 13:19:04,428 DEBUG   HandlerThread:4023993 [handler.py:handle_request():146] handle_request: keepalive
2024-12-21 13:19:09,430 DEBUG   HandlerThread:4023993 [handler.py:handle_request():146] handle_request: keepalive
2024-12-21 13:19:14,432 DEBUG   HandlerThread:4023993 [handler.py:handle_request():146] handle_request: keepalive
2024-12-21 13:19:17,374 DEBUG   SystemMonitor:4023993 [system_monitor.py:_start():172] Starting system metrics aggregation loop
2024-12-21 13:19:19,434 DEBUG   HandlerThread:4023993 [handler.py:handle_request():146] handle_request: keepalive
2024-12-21 13:19:24,436 DEBUG   HandlerThread:4023993 [handler.py:handle_request():146] handle_request: keepalive
2024-12-21 13:19:29,438 DEBUG   HandlerThread:4023993 [handler.py:handle_request():146] handle_request: keepalive
2024-12-21 13:19:34,440 DEBUG   HandlerThread:4023993 [handler.py:handle_request():146] handle_request: keepalive
2024-12-21 13:19:39,443 DEBUG   HandlerThread:4023993 [handler.py:handle_request():146] handle_request: keepalive
2024-12-21 13:19:44,444 DEBUG   HandlerThread:4023993 [handler.py:handle_request():146] handle_request: keepalive
2024-12-21 13:19:49,447 DEBUG   HandlerThread:4023993 [handler.py:handle_request():146] handle_request: keepalive
2024-12-21 13:19:54,450 DEBUG   HandlerThread:4023993 [handler.py:handle_request():146] handle_request: keepalive
2024-12-21 13:19:59,453 DEBUG   HandlerThread:4023993 [handler.py:handle_request():146] handle_request: keepalive
2024-12-21 13:20:04,455 DEBUG   HandlerThread:4023993 [handler.py:handle_request():146] handle_request: keepalive
2024-12-21 13:20:09,457 DEBUG   HandlerThread:4023993 [handler.py:handle_request():146] handle_request: keepalive
2024-12-21 13:20:14,459 DEBUG   HandlerThread:4023993 [handler.py:handle_request():146] handle_request: keepalive
2024-12-21 13:20:19,461 DEBUG   HandlerThread:4023993 [handler.py:handle_request():146] handle_request: keepalive
2024-12-21 13:20:24,462 DEBUG   HandlerThread:4023993 [handler.py:handle_request():146] handle_request: keepalive
2024-12-21 13:20:29,465 DEBUG   HandlerThread:4023993 [handler.py:handle_request():146] handle_request: keepalive
2024-12-21 13:20:31,466 INFO    memory    :4023993 [interfaces.py:monitor():140] Process proc.memory.rssMB has exited.
2024-12-21 13:20:31,467 DEBUG   SystemMonitor:4023993 [system_monitor.py:_start():179] Finished system metrics aggregation loop
2024-12-21 13:20:31,468 DEBUG   SystemMonitor:4023993 [system_monitor.py:_start():183] Publishing last batch of metrics
2024-12-21 13:20:34,466 DEBUG   HandlerThread:4023993 [handler.py:handle_request():146] handle_request: keepalive
2024-12-21 13:20:36,470 WARNING StreamThr :4023993 [internal.py:is_dead():414] Internal process exiting, parent pid 4017041 disappeared
2024-12-21 13:20:36,470 ERROR   StreamThr :4023993 [internal.py:wandb_internal():152] Internal process shutdown.
2024-12-21 13:20:36,476 INFO    WriterThread:4023993 [datastore.py:close():296] close: /home/wangc/now/pure/ALinAirway/wandb/run-20241221_131723-9lwe4ti5/run-9lwe4ti5.wandb
2024-12-21 13:20:37,467 INFO    HandlerThread:4023993 [handler.py:finish():866] shutting down handler
2024-12-21 13:20:37,467 INFO    HandlerThread:4023993 [system_monitor.py:finish():203] Stopping system monitor
2024-12-21 13:20:37,468 INFO    HandlerThread:4023993 [interfaces.py:finish():202] Joined cpu monitor
2024-12-21 13:20:37,468 INFO    HandlerThread:4023993 [interfaces.py:finish():202] Joined disk monitor
2024-12-21 13:20:37,468 INFO    HandlerThread:4023993 [interfaces.py:finish():202] Joined gpu monitor
2024-12-21 13:20:37,469 INFO    HandlerThread:4023993 [interfaces.py:finish():202] Joined memory monitor
2024-12-21 13:20:37,469 INFO    HandlerThread:4023993 [interfaces.py:finish():202] Joined network monitor
2024-12-21 13:21:04,672 WARNING FileStreamThread:4023993 [file_stream.py:request_with_retry():687] requests_with_retry encountered retryable exception: HTTPSConnectionPool(host='api.wandb.ai', port=443): Max retries exceeded with url: /files/a783208746-no/navi_airway/9lwe4ti5/file_stream (Caused by NewConnectionError('<urllib3.connection.HTTPSConnection object at 0x7fa25d17c7f0>: Failed to establish a new connection: [Errno 110] Connection timed out')). func: functools.partial(<bound method Session.post of <requests.sessions.Session object at 0x7fa25d404790>>, timeout=180.0), args: ('https://api.wandb.ai/files/a783208746-no/navi_airway/9lwe4ti5/file_stream',), kwargs: {'json': {'complete': False, 'failed': False, 'dropped': 0, 'uploaded': []}}
2024-12-21 13:24:33,432 WARNING FileStreamThread:4023993 [file_stream.py:request_with_retry():687] requests_with_retry encountered retryable exception: HTTPSConnectionPool(host='api.wandb.ai', port=443): Read timed out. (read timeout=180.0). func: functools.partial(<bound method Session.post of <requests.sessions.Session object at 0x7fa25d404790>>, timeout=180.0), args: ('https://api.wandb.ai/files/a783208746-no/navi_airway/9lwe4ti5/file_stream',), kwargs: {'json': {'complete': False, 'failed': False, 'dropped': 0, 'uploaded': []}}
2024-12-21 13:28:06,900 WARNING FileStreamThread:4023993 [file_stream.py:request_with_retry():687] requests_with_retry encountered retryable exception: HTTPSConnectionPool(host='api.wandb.ai', port=443): Read timed out. (read timeout=180.0). func: functools.partial(<bound method Session.post of <requests.sessions.Session object at 0x7fa25d404790>>, timeout=180.0), args: ('https://api.wandb.ai/files/a783208746-no/navi_airway/9lwe4ti5/file_stream',), kwargs: {'json': {'complete': False, 'failed': False, 'dropped': 0, 'uploaded': []}}
2024-12-21 13:31:18,991 INFO    wandb-upload_0:4023993 [upload_job.py:push():131] Uploaded file /tmp/tmpr9yoeux9wandb/g18x25rs-wandb-metadata.json
2024-12-21 13:31:40,319 WARNING FileStreamThread:4023993 [file_stream.py:request_with_retry():687] requests_with_retry encountered retryable exception: HTTPSConnectionPool(host='api.wandb.ai', port=443): Read timed out. (read timeout=180.0). func: functools.partial(<bound method Session.post of <requests.sessions.Session object at 0x7fa25d404790>>, timeout=180.0), args: ('https://api.wandb.ai/files/a783208746-no/navi_airway/9lwe4ti5/file_stream',), kwargs: {'json': {'complete': False, 'failed': False, 'dropped': 0, 'uploaded': []}}
2024-12-21 13:38:16,494 WARNING FileStreamThread:4023993 [file_stream.py:request_with_retry():687] requests_with_retry encountered retryable exception: HTTPSConnectionPool(host='api.wandb.ai', port=443): Read timed out. (read timeout=180.0). func: functools.partial(<bound method Session.post of <requests.sessions.Session object at 0x7fa25d404790>>, timeout=180.0), args: ('https://api.wandb.ai/files/a783208746-no/navi_airway/9lwe4ti5/file_stream',), kwargs: {'json': {'complete': False, 'failed': False, 'dropped': 0, 'uploaded': []}}
2024-12-21 13:44:17,625 INFO    SenderThread:4023993 [retry.py:__call__():172] Retry attempt failed:
Traceback (most recent call last):
  File "/home/wangc/anaconda3/envs/test1/lib/python3.8/site-packages/urllib3/connection.py", line 174, in _new_conn
    conn = connection.create_connection(
  File "/home/wangc/anaconda3/envs/test1/lib/python3.8/site-packages/urllib3/util/connection.py", line 95, in create_connection
    raise err
  File "/home/wangc/anaconda3/envs/test1/lib/python3.8/site-packages/urllib3/util/connection.py", line 85, in create_connection
    sock.connect(sa)
socket.timeout: timed out

During handling of the above exception, another exception occurred:

Traceback (most recent call last):
  File "/home/wangc/anaconda3/envs/test1/lib/python3.8/site-packages/urllib3/connectionpool.py", line 703, in urlopen
    httplib_response = self._make_request(
  File "/home/wangc/anaconda3/envs/test1/lib/python3.8/site-packages/urllib3/connectionpool.py", line 386, in _make_request
    self._validate_conn(conn)
  File "/home/wangc/anaconda3/envs/test1/lib/python3.8/site-packages/urllib3/connectionpool.py", line 1042, in _validate_conn
    conn.connect()
  File "/home/wangc/anaconda3/envs/test1/lib/python3.8/site-packages/urllib3/connection.py", line 358, in connect
    self.sock = conn = self._new_conn()
  File "/home/wangc/anaconda3/envs/test1/lib/python3.8/site-packages/urllib3/connection.py", line 179, in _new_conn
    raise ConnectTimeoutError(
urllib3.exceptions.ConnectTimeoutError: (<urllib3.connection.HTTPSConnection object at 0x7fa25d1893a0>, 'Connection to api.wandb.ai timed out. (connect timeout=20)')

During handling of the above exception, another exception occurred:

Traceback (most recent call last):
  File "/home/wangc/anaconda3/envs/test1/lib/python3.8/site-packages/requests/adapters.py", line 489, in send
    resp = conn.urlopen(
  File "/home/wangc/anaconda3/envs/test1/lib/python3.8/site-packages/urllib3/connectionpool.py", line 787, in urlopen
    retries = retries.increment(
  File "/home/wangc/anaconda3/envs/test1/lib/python3.8/site-packages/urllib3/util/retry.py", line 592, in increment
    raise MaxRetryError(_pool, url, error or ResponseError(cause))
urllib3.exceptions.MaxRetryError: HTTPSConnectionPool(host='api.wandb.ai', port=443): Max retries exceeded with url: /graphql (Caused by ConnectTimeoutError(<urllib3.connection.HTTPSConnection object at 0x7fa25d1893a0>, 'Connection to api.wandb.ai timed out. (connect timeout=20)'))

During handling of the above exception, another exception occurred:

Traceback (most recent call last):
  File "/home/wangc/anaconda3/envs/test1/lib/python3.8/site-packages/wandb/sdk/lib/retry.py", line 131, in __call__
    result = self._call_fn(*args, **kwargs)
  File "/home/wangc/anaconda3/envs/test1/lib/python3.8/site-packages/wandb/sdk/internal/internal_api.py", line 369, in execute
    return self.client.execute(*args, **kwargs)  # type: ignore
  File "/home/wangc/anaconda3/envs/test1/lib/python3.8/site-packages/wandb/vendor/gql-0.2.0/wandb_gql/client.py", line 52, in execute
    result = self._get_result(document, *args, **kwargs)
  File "/home/wangc/anaconda3/envs/test1/lib/python3.8/site-packages/wandb/vendor/gql-0.2.0/wandb_gql/client.py", line 60, in _get_result
    return self.transport.execute(document, *args, **kwargs)
  File "/home/wangc/anaconda3/envs/test1/lib/python3.8/site-packages/wandb/sdk/lib/gql_request.py", line 58, in execute
    request = self.session.post(self.url, **post_args)
  File "/home/wangc/anaconda3/envs/test1/lib/python3.8/site-packages/requests/sessions.py", line 635, in post
    return self.request("POST", url, data=data, json=json, **kwargs)
  File "/home/wangc/anaconda3/envs/test1/lib/python3.8/site-packages/requests/sessions.py", line 587, in request
    resp = self.send(prep, **send_kwargs)
  File "/home/wangc/anaconda3/envs/test1/lib/python3.8/site-packages/requests/sessions.py", line 701, in send
    r = adapter.send(request, **kwargs)
  File "/home/wangc/anaconda3/envs/test1/lib/python3.8/site-packages/requests/adapters.py", line 553, in send
    raise ConnectTimeout(e, request=request)
requests.exceptions.ConnectTimeout: HTTPSConnectionPool(host='api.wandb.ai', port=443): Max retries exceeded with url: /graphql (Caused by ConnectTimeoutError(<urllib3.connection.HTTPSConnection object at 0x7fa25d1893a0>, 'Connection to api.wandb.ai timed out. (connect timeout=20)'))
2024-12-21 13:45:22,610 WARNING FileStreamThread:4023993 [file_stream.py:request_with_retry():687] requests_with_retry encountered retryable exception: HTTPSConnectionPool(host='api.wandb.ai', port=443): Read timed out. (read timeout=180.0). func: functools.partial(<bound method Session.post of <requests.sessions.Session object at 0x7fa25d404790>>, timeout=180.0), args: ('https://api.wandb.ai/files/a783208746-no/navi_airway/9lwe4ti5/file_stream',), kwargs: {'json': {'complete': False, 'failed': False, 'dropped': 0, 'uploaded': []}}
2024-12-21 13:47:35,968 WARNING FileStreamThread:4023993 [file_stream.py:request_with_retry():687] requests_with_retry encountered retryable exception: HTTPSConnectionPool(host='api.wandb.ai', port=443): Max retries exceeded with url: /files/a783208746-no/navi_airway/9lwe4ti5/file_stream (Caused by NewConnectionError('<urllib3.connection.HTTPSConnection object at 0x7fa25d0db160>: Failed to establish a new connection: [Errno 110] Connection timed out')). func: functools.partial(<bound method Session.post of <requests.sessions.Session object at 0x7fa25d404790>>, timeout=180.0), args: ('https://api.wandb.ai/files/a783208746-no/navi_airway/9lwe4ti5/file_stream',), kwargs: {'json': {'complete': False, 'failed': False, 'dropped': 0, 'uploaded': []}}
2024-12-21 13:49:51,136 WARNING FileStreamThread:4023993 [file_stream.py:request_with_retry():687] requests_with_retry encountered retryable exception: HTTPSConnectionPool(host='api.wandb.ai', port=443): Max retries exceeded with url: /files/a783208746-no/navi_airway/9lwe4ti5/file_stream (Caused by NewConnectionError('<urllib3.connection.HTTPSConnection object at 0x7fa25d103f40>: Failed to establish a new connection: [Errno 110] Connection timed out')). func: functools.partial(<bound method Session.post of <requests.sessions.Session object at 0x7fa25d404790>>, timeout=180.0), args: ('https://api.wandb.ai/files/a783208746-no/navi_airway/9lwe4ti5/file_stream',), kwargs: {'json': {'complete': False, 'failed': False, 'dropped': 0, 'uploaded': []}}
2024-12-21 13:52:10,404 WARNING FileStreamThread:4023993 [file_stream.py:request_with_retry():687] requests_with_retry encountered retryable exception: HTTPSConnectionPool(host='api.wandb.ai', port=443): Max retries exceeded with url: /files/a783208746-no/navi_airway/9lwe4ti5/file_stream (Caused by NewConnectionError('<urllib3.connection.HTTPSConnection object at 0x7fa25d304e80>: Failed to establish a new connection: [Errno 110] Connection timed out')). func: functools.partial(<bound method Session.post of <requests.sessions.Session object at 0x7fa25d404790>>, timeout=180.0), args: ('https://api.wandb.ai/files/a783208746-no/navi_airway/9lwe4ti5/file_stream',), kwargs: {'json': {'complete': False, 'failed': False, 'dropped': 0, 'uploaded': []}}
2024-12-21 13:54:39,904 WARNING FileStreamThread:4023993 [file_stream.py:request_with_retry():687] requests_with_retry encountered retryable exception: HTTPSConnectionPool(host='api.wandb.ai', port=443): Max retries exceeded with url: /files/a783208746-no/navi_airway/9lwe4ti5/file_stream (Caused by NewConnectionError('<urllib3.connection.HTTPSConnection object at 0x7fa25d189910>: Failed to establish a new connection: [Errno 110] Connection timed out')). func: functools.partial(<bound method Session.post of <requests.sessions.Session object at 0x7fa25d404790>>, timeout=180.0), args: ('https://api.wandb.ai/files/a783208746-no/navi_airway/9lwe4ti5/file_stream',), kwargs: {'json': {'complete': False, 'failed': False, 'dropped': 0, 'uploaded': []}}
2024-12-21 13:57:27,840 WARNING FileStreamThread:4023993 [file_stream.py:request_with_retry():687] requests_with_retry encountered retryable exception: HTTPSConnectionPool(host='api.wandb.ai', port=443): Max retries exceeded with url: /files/a783208746-no/navi_airway/9lwe4ti5/file_stream (Caused by NewConnectionError('<urllib3.connection.HTTPSConnection object at 0x7fa25d28b070>: Failed to establish a new connection: [Errno 110] Connection timed out')). func: functools.partial(<bound method Session.post of <requests.sessions.Session object at 0x7fa25d404790>>, timeout=180.0), args: ('https://api.wandb.ai/files/a783208746-no/navi_airway/9lwe4ti5/file_stream',), kwargs: {'json': {'complete': False, 'failed': False, 'dropped': 0, 'uploaded': []}}
2024-12-21 14:00:31,259 INFO    SenderThread:4023993 [sender.py:finish():1546] shutting down sender
2024-12-21 14:00:31,259 INFO    SenderThread:4023993 [dir_watcher.py:finish():358] shutting down directory watcher
2024-12-21 14:00:31,505 INFO    SenderThread:4023993 [dir_watcher.py:finish():388] scan: /home/wangc/now/pure/ALinAirway/wandb/run-20241221_131723-9lwe4ti5/files
2024-12-21 14:00:31,505 INFO    SenderThread:4023993 [dir_watcher.py:finish():402] scan save: /home/wangc/now/pure/ALinAirway/wandb/run-20241221_131723-9lwe4ti5/files/config.yaml config.yaml
2024-12-21 14:00:31,506 INFO    SenderThread:4023993 [dir_watcher.py:finish():402] scan save: /home/wangc/now/pure/ALinAirway/wandb/run-20241221_131723-9lwe4ti5/files/conda-environment.yaml conda-environment.yaml
2024-12-21 14:00:31,506 INFO    SenderThread:4023993 [dir_watcher.py:finish():402] scan save: /home/wangc/now/pure/ALinAirway/wandb/run-20241221_131723-9lwe4ti5/files/wandb-metadata.json wandb-metadata.json
2024-12-21 14:00:31,506 INFO    SenderThread:4023993 [dir_watcher.py:finish():402] scan save: /home/wangc/now/pure/ALinAirway/wandb/run-20241221_131723-9lwe4ti5/files/requirements.txt requirements.txt
2024-12-21 14:00:31,518 INFO    SenderThread:4023993 [file_pusher.py:finish():172] shutting down file pusher
2024-12-21 14:00:31,518 INFO    SenderThread:4023993 [file_pusher.py:join():178] waiting for file pusher
2024-12-21 14:00:32,956 INFO    wandb-upload_0:4023993 [upload_job.py:push():131] Uploaded file /home/wangc/now/pure/ALinAirway/wandb/run-20241221_131723-9lwe4ti5/files/config.yaml
2024-12-21 14:00:33,565 INFO    wandb-upload_2:4023993 [upload_job.py:push():131] Uploaded file /home/wangc/now/pure/ALinAirway/wandb/run-20241221_131723-9lwe4ti5/files/requirements.txt
2024-12-21 14:00:33,577 INFO    wandb-upload_1:4023993 [upload_job.py:push():131] Uploaded file /home/wangc/now/pure/ALinAirway/wandb/run-20241221_131723-9lwe4ti5/files/conda-environment.yaml
2024-12-21 14:00:34,022 INFO    SenderThread:4023993 [file_stream.py:finish():614] file stream finish called
2024-12-21 14:00:34,476 INFO    SenderThread:4023993 [file_stream.py:finish():618] file stream finish is done
