2024-12-22 12:16:57,338 INFO    StreamThr :943190 [internal.py:wandb_internal():86] W&B internal server running at pid: 943190, started at: 2024-12-22 12:16:57.336921
2024-12-22 12:16:57,341 DEBUG   HandlerThread:943190 [handler.py:handle_request():146] handle_request: status
2024-12-22 12:16:57,345 INFO    WriterThread:943190 [datastore.py:open_for_write():87] open: /home/wangc/now/pure/ALinAirway/wandb/run-20241222_121657-hbd43cf1/run-hbd43cf1.wandb
2024-12-22 12:16:57,348 DEBUG   SenderThread:943190 [sender.py:send():379] send: header
2024-12-22 12:16:57,431 DEBUG   SenderThread:943190 [sender.py:send():379] send: run
2024-12-22 12:17:02,433 DEBUG   HandlerThread:943190 [handler.py:handle_request():146] handle_request: keepalive
2024-12-22 12:17:07,434 DEBUG   HandlerThread:943190 [handler.py:handle_request():146] handle_request: keepalive
2024-12-22 12:17:12,436 DEBUG   HandlerThread:943190 [handler.py:handle_request():146] handle_request: keepalive
2024-12-22 12:17:17,438 DEBUG   HandlerThread:943190 [handler.py:handle_request():146] handle_request: keepalive
2024-12-22 12:17:22,440 DEBUG   HandlerThread:943190 [handler.py:handle_request():146] handle_request: keepalive
2024-12-22 12:17:27,442 DEBUG   HandlerThread:943190 [handler.py:handle_request():146] handle_request: keepalive
2024-12-22 12:17:32,444 DEBUG   HandlerThread:943190 [handler.py:handle_request():146] handle_request: keepalive
2024-12-22 12:17:37,445 DEBUG   HandlerThread:943190 [handler.py:handle_request():146] handle_request: keepalive
2024-12-22 12:17:42,447 DEBUG   HandlerThread:943190 [handler.py:handle_request():146] handle_request: keepalive
2024-12-22 12:17:47,449 DEBUG   HandlerThread:943190 [handler.py:handle_request():146] handle_request: keepalive
2024-12-22 12:17:52,451 DEBUG   HandlerThread:943190 [handler.py:handle_request():146] handle_request: keepalive
2024-12-22 12:17:57,453 DEBUG   HandlerThread:943190 [handler.py:handle_request():146] handle_request: keepalive
2024-12-22 12:18:01,416 INFO    SenderThread:943190 [retry.py:__call__():172] Retry attempt failed:
Traceback (most recent call last):
  File "/home/wangc/anaconda3/envs/test1/lib/python3.8/site-packages/urllib3/connection.py", line 174, in _new_conn
    conn = connection.create_connection(
  File "/home/wangc/anaconda3/envs/test1/lib/python3.8/site-packages/urllib3/util/connection.py", line 95, in create_connection
    raise err
  File "/home/wangc/anaconda3/envs/test1/lib/python3.8/site-packages/urllib3/util/connection.py", line 85, in create_connection
    sock.connect(sa)
socket.timeout: timed out

During handling of the above exception, another exception occurred:

Traceback (most recent call last):
  File "/home/wangc/anaconda3/envs/test1/lib/python3.8/site-packages/urllib3/connectionpool.py", line 703, in urlopen
    httplib_response = self._make_request(
  File "/home/wangc/anaconda3/envs/test1/lib/python3.8/site-packages/urllib3/connectionpool.py", line 386, in _make_request
    self._validate_conn(conn)
  File "/home/wangc/anaconda3/envs/test1/lib/python3.8/site-packages/urllib3/connectionpool.py", line 1042, in _validate_conn
    conn.connect()
  File "/home/wangc/anaconda3/envs/test1/lib/python3.8/site-packages/urllib3/connection.py", line 358, in connect
    self.sock = conn = self._new_conn()
  File "/home/wangc/anaconda3/envs/test1/lib/python3.8/site-packages/urllib3/connection.py", line 179, in _new_conn
    raise ConnectTimeoutError(
urllib3.exceptions.ConnectTimeoutError: (<urllib3.connection.HTTPSConnection object at 0x7f1ecf1b06a0>, 'Connection to api.wandb.ai timed out. (connect timeout=20)')

During handling of the above exception, another exception occurred:

Traceback (most recent call last):
  File "/home/wangc/anaconda3/envs/test1/lib/python3.8/site-packages/requests/adapters.py", line 489, in send
    resp = conn.urlopen(
  File "/home/wangc/anaconda3/envs/test1/lib/python3.8/site-packages/urllib3/connectionpool.py", line 787, in urlopen
    retries = retries.increment(
  File "/home/wangc/anaconda3/envs/test1/lib/python3.8/site-packages/urllib3/util/retry.py", line 592, in increment
    raise MaxRetryError(_pool, url, error or ResponseError(cause))
urllib3.exceptions.MaxRetryError: HTTPSConnectionPool(host='api.wandb.ai', port=443): Max retries exceeded with url: /graphql (Caused by ConnectTimeoutError(<urllib3.connection.HTTPSConnection object at 0x7f1ecf1b06a0>, 'Connection to api.wandb.ai timed out. (connect timeout=20)'))

During handling of the above exception, another exception occurred:

Traceback (most recent call last):
  File "/home/wangc/anaconda3/envs/test1/lib/python3.8/site-packages/wandb/sdk/lib/retry.py", line 131, in __call__
    result = self._call_fn(*args, **kwargs)
  File "/home/wangc/anaconda3/envs/test1/lib/python3.8/site-packages/wandb/sdk/internal/internal_api.py", line 369, in execute
    return self.client.execute(*args, **kwargs)  # type: ignore
  File "/home/wangc/anaconda3/envs/test1/lib/python3.8/site-packages/wandb/vendor/gql-0.2.0/wandb_gql/client.py", line 52, in execute
    result = self._get_result(document, *args, **kwargs)
  File "/home/wangc/anaconda3/envs/test1/lib/python3.8/site-packages/wandb/vendor/gql-0.2.0/wandb_gql/client.py", line 60, in _get_result
    return self.transport.execute(document, *args, **kwargs)
  File "/home/wangc/anaconda3/envs/test1/lib/python3.8/site-packages/wandb/sdk/lib/gql_request.py", line 58, in execute
    request = self.session.post(self.url, **post_args)
  File "/home/wangc/anaconda3/envs/test1/lib/python3.8/site-packages/requests/sessions.py", line 635, in post
    return self.request("POST", url, data=data, json=json, **kwargs)
  File "/home/wangc/anaconda3/envs/test1/lib/python3.8/site-packages/requests/sessions.py", line 587, in request
    resp = self.send(prep, **send_kwargs)
  File "/home/wangc/anaconda3/envs/test1/lib/python3.8/site-packages/requests/sessions.py", line 701, in send
    r = adapter.send(request, **kwargs)
  File "/home/wangc/anaconda3/envs/test1/lib/python3.8/site-packages/requests/adapters.py", line 553, in send
    raise ConnectTimeout(e, request=request)
requests.exceptions.ConnectTimeout: HTTPSConnectionPool(host='api.wandb.ai', port=443): Max retries exceeded with url: /graphql (Caused by ConnectTimeoutError(<urllib3.connection.HTTPSConnection object at 0x7f1ecf1b06a0>, 'Connection to api.wandb.ai timed out. (connect timeout=20)'))
2024-12-22 12:18:02,454 DEBUG   HandlerThread:943190 [handler.py:handle_request():146] handle_request: keepalive
2024-12-22 12:18:07,456 DEBUG   HandlerThread:943190 [handler.py:handle_request():146] handle_request: keepalive
2024-12-22 12:18:12,458 DEBUG   HandlerThread:943190 [handler.py:handle_request():146] handle_request: keepalive
2024-12-22 12:18:17,459 DEBUG   HandlerThread:943190 [handler.py:handle_request():146] handle_request: keepalive
2024-12-22 12:18:22,461 DEBUG   HandlerThread:943190 [handler.py:handle_request():146] handle_request: keepalive
2024-12-22 12:18:27,463 DEBUG   HandlerThread:943190 [handler.py:handle_request():146] handle_request: cancel
2024-12-22 12:18:27,464 DEBUG   HandlerThread:943190 [handler.py:handle_request():146] handle_request: cancel
2024-12-22 12:18:27,465 DEBUG   SenderThread:943190 [sender.py:send():388] Record cancelled: run
2024-12-22 12:18:27,465 DEBUG   HandlerThread:943190 [handler.py:handle_request():146] handle_request: status_report
2024-12-22 12:18:28,321 DEBUG   HandlerThread:943190 [handler.py:handle_request():146] handle_request: shutdown
2024-12-22 12:18:28,322 INFO    HandlerThread:943190 [handler.py:finish():866] shutting down handler
2024-12-22 12:18:28,465 INFO    SenderThread:943190 [sender.py:finish():1546] shutting down sender
2024-12-22 12:18:28,466 INFO    WriterThread:943190 [datastore.py:close():296] close: /home/wangc/now/pure/ALinAirway/wandb/run-20241222_121657-hbd43cf1/run-hbd43cf1.wandb
