2024-12-19 03:31:10,849 INFO    StreamThr :161208 [internal.py:wandb_internal():86] W&B internal server running at pid: 161208, started at: 2024-12-19 03:31:10.847369
2024-12-19 03:31:10,852 DEBUG   HandlerThread:161208 [handler.py:handle_request():146] handle_request: status
2024-12-19 03:31:10,860 INFO    WriterThread:161208 [datastore.py:open_for_write():87] open: /home/wangc/now/pure/ALinAirway/wandb/run-20241219_033110-mpc490pd/run-mpc490pd.wandb
2024-12-19 03:31:10,861 DEBUG   SenderThread:161208 [sender.py:send():379] send: header
2024-12-19 03:31:10,969 DEBUG   SenderThread:161208 [sender.py:send():379] send: run
2024-12-19 03:31:12,352 ERROR   SenderThread:161208 [internal_api.py:execute():373] 404 response executing GraphQL.
2024-12-19 03:31:12,352 ERROR   SenderThread:161208 [internal_api.py:execute():374] {"errors":[{"message":"entity t_green not found during upsertBucket","path":["upsertBucket"]}],"data":{"upsertBucket":null}}
2024-12-19 03:31:12,355 ERROR   SenderThread:161208 [sender.py:send_run():971] It appears that you do not have permission to access the requested resource. Please reach out to the project owner to grant you access. If you have the correct permissions, verify that there are no issues with your networking setup.(Error 404: Not Found)
Traceback (most recent call last):
  File "/home/wangc/anaconda3/envs/test1/lib/python3.8/site-packages/wandb/sdk/lib/retry.py", line 131, in __call__
    result = self._call_fn(*args, **kwargs)
  File "/home/wangc/anaconda3/envs/test1/lib/python3.8/site-packages/wandb/sdk/internal/internal_api.py", line 369, in execute
    return self.client.execute(*args, **kwargs)  # type: ignore
  File "/home/wangc/anaconda3/envs/test1/lib/python3.8/site-packages/wandb/vendor/gql-0.2.0/wandb_gql/client.py", line 52, in execute
    result = self._get_result(document, *args, **kwargs)
  File "/home/wangc/anaconda3/envs/test1/lib/python3.8/site-packages/wandb/vendor/gql-0.2.0/wandb_gql/client.py", line 60, in _get_result
    return self.transport.execute(document, *args, **kwargs)
  File "/home/wangc/anaconda3/envs/test1/lib/python3.8/site-packages/wandb/sdk/lib/gql_request.py", line 59, in execute
    request.raise_for_status()
  File "/home/wangc/anaconda3/envs/test1/lib/python3.8/site-packages/requests/models.py", line 1021, in raise_for_status
    raise HTTPError(http_error_msg, response=self)
requests.exceptions.HTTPError: 404 Client Error: Not Found for url: https://api.wandb.ai/graphql

During handling of the above exception, another exception occurred:

Traceback (most recent call last):
  File "/home/wangc/anaconda3/envs/test1/lib/python3.8/site-packages/wandb/sdk/internal/sender.py", line 969, in send_run
    server_run = self._init_run(run, config_value_dict)
  File "/home/wangc/anaconda3/envs/test1/lib/python3.8/site-packages/wandb/sdk/internal/sender.py", line 1014, in _init_run
    server_run, inserted, server_messages = self._api.upsert_run(
  File "/home/wangc/anaconda3/envs/test1/lib/python3.8/site-packages/wandb/apis/normalize.py", line 73, in wrapper
    raise err
  File "/home/wangc/anaconda3/envs/test1/lib/python3.8/site-packages/wandb/apis/normalize.py", line 41, in wrapper
    return func(*args, **kwargs)
  File "/home/wangc/anaconda3/envs/test1/lib/python3.8/site-packages/wandb/sdk/internal/internal_api.py", line 2217, in upsert_run
    response = self.gql(
  File "/home/wangc/anaconda3/envs/test1/lib/python3.8/site-packages/wandb/sdk/internal/internal_api.py", line 341, in gql
    ret = self._retry_gql(
  File "/home/wangc/anaconda3/envs/test1/lib/python3.8/site-packages/wandb/sdk/lib/retry.py", line 147, in __call__
    retry_timedelta_triggered = check_retry_fn(e)
  File "/home/wangc/anaconda3/envs/test1/lib/python3.8/site-packages/wandb/util.py", line 968, in check_retry_fn
    return fallback_retry_fn(e)
  File "/home/wangc/anaconda3/envs/test1/lib/python3.8/site-packages/wandb/util.py", line 910, in no_retry_auth
    raise CommError(
wandb.errors.CommError: It appears that you do not have permission to access the requested resource. Please reach out to the project owner to grant you access. If you have the correct permissions, verify that there are no issues with your networking setup.(Error 404: Not Found)
2024-12-19 03:31:13,159 DEBUG   HandlerThread:161208 [handler.py:handle_request():146] handle_request: shutdown
2024-12-19 03:31:13,159 INFO    HandlerThread:161208 [handler.py:finish():866] shutting down handler
2024-12-19 03:31:13,361 INFO    SenderThread:161208 [sender.py:finish():1546] shutting down sender
2024-12-19 03:31:13,970 INFO    WriterThread:161208 [datastore.py:close():296] close: /home/wangc/now/pure/ALinAirway/wandb/run-20241219_033110-mpc490pd/run-mpc490pd.wandb
