2024-12-21 13:08:42,648 INFO    MainThread:3645908 [wandb_setup.py:_flush():76] Current SDK version is 0.16.6
2024-12-21 13:08:42,648 INFO    MainThread:3645908 [wandb_setup.py:_flush():76] Configure stats pid to 3645908
2024-12-21 13:08:42,649 INFO    MainThread:3645908 [wandb_setup.py:_flush():76] Loading settings from /home/wangc/.config/wandb/settings
2024-12-21 13:08:42,649 INFO    MainThread:3645908 [wandb_setup.py:_flush():76] Loading settings from /home/wangc/now/pure/ALinAirway/wandb/settings
2024-12-21 13:08:42,649 INFO    MainThread:3645908 [wandb_setup.py:_flush():76] Loading settings from environment variables: {}
2024-12-21 13:08:42,649 INFO    MainThread:3645908 [wandb_setup.py:_flush():76] Applying setup settings: {'_disable_service': False}
2024-12-21 13:08:42,649 INFO    MainThread:3645908 [wandb_setup.py:_flush():76] Inferring run settings from compute environment: {'program_relpath': 'train_green_t.py', 'program_abspath': '/home/wangc/now/pure/ALinAirway/train_green_t.py', 'program': 'train_green_t.py'}
2024-12-21 13:08:42,649 INFO    MainThread:3645908 [wandb_setup.py:_flush():76] Applying login settings: {}
2024-12-21 13:08:42,649 INFO    MainThread:3645908 [wandb_init.py:_log_setup():521] Logging user logs to /home/wangc/now/pure/ALinAirway/wandb/run-20241221_130842-e932yuog/logs/debug.log
2024-12-21 13:08:42,650 INFO    MainThread:3645908 [wandb_init.py:_log_setup():522] Logging internal logs to /home/wangc/now/pure/ALinAirway/wandb/run-20241221_130842-e932yuog/logs/debug-internal.log
2024-12-21 13:08:42,650 INFO    MainThread:3645908 [wandb_init.py:init():561] calling init triggers
2024-12-21 13:08:42,650 INFO    MainThread:3645908 [wandb_init.py:init():568] wandb.init called with sweep_config: {}
config: {'learning_rate': 1e-05, 'max_epoch': 50, 'batch_size': 12}
2024-12-21 13:08:42,650 INFO    MainThread:3645908 [wandb_init.py:init():611] starting backend
2024-12-21 13:08:42,650 INFO    MainThread:3645908 [wandb_init.py:init():615] setting up manager
2024-12-21 13:08:42,656 INFO    MainThread:3645908 [backend.py:_multiprocessing_setup():105] multiprocessing start_methods=fork,spawn,forkserver, using: spawn
2024-12-21 13:08:42,660 INFO    MainThread:3645908 [wandb_init.py:init():623] backend started and connected
2024-12-21 13:08:42,676 INFO    MainThread:3645908 [wandb_init.py:init():715] updated telemetry
2024-12-21 13:08:42,825 INFO    MainThread:3645908 [wandb_init.py:init():748] communicating run to backend with 90.0 second timeout
2024-12-21 13:09:41,346 INFO    Thread-1  :3645908 [retry.py:__call__():172] Retry attempt failed:
Traceback (most recent call last):
  File "/home/wangc/anaconda3/envs/test1/lib/python3.8/site-packages/urllib3/connection.py", line 174, in _new_conn
    conn = connection.create_connection(
  File "/home/wangc/anaconda3/envs/test1/lib/python3.8/site-packages/urllib3/util/connection.py", line 95, in create_connection
    raise err
  File "/home/wangc/anaconda3/envs/test1/lib/python3.8/site-packages/urllib3/util/connection.py", line 85, in create_connection
    sock.connect(sa)
socket.timeout: timed out

During handling of the above exception, another exception occurred:

Traceback (most recent call last):
  File "/home/wangc/anaconda3/envs/test1/lib/python3.8/site-packages/urllib3/connectionpool.py", line 703, in urlopen
    httplib_response = self._make_request(
  File "/home/wangc/anaconda3/envs/test1/lib/python3.8/site-packages/urllib3/connectionpool.py", line 386, in _make_request
    self._validate_conn(conn)
  File "/home/wangc/anaconda3/envs/test1/lib/python3.8/site-packages/urllib3/connectionpool.py", line 1042, in _validate_conn
    conn.connect()
  File "/home/wangc/anaconda3/envs/test1/lib/python3.8/site-packages/urllib3/connection.py", line 358, in connect
    self.sock = conn = self._new_conn()
  File "/home/wangc/anaconda3/envs/test1/lib/python3.8/site-packages/urllib3/connection.py", line 179, in _new_conn
    raise ConnectTimeoutError(
urllib3.exceptions.ConnectTimeoutError: (<urllib3.connection.HTTPSConnection object at 0x7f950ba072e0>, 'Connection to api.wandb.ai timed out. (connect timeout=20)')

During handling of the above exception, another exception occurred:

Traceback (most recent call last):
  File "/home/wangc/anaconda3/envs/test1/lib/python3.8/site-packages/requests/adapters.py", line 489, in send
    resp = conn.urlopen(
  File "/home/wangc/anaconda3/envs/test1/lib/python3.8/site-packages/urllib3/connectionpool.py", line 787, in urlopen
    retries = retries.increment(
  File "/home/wangc/anaconda3/envs/test1/lib/python3.8/site-packages/urllib3/util/retry.py", line 592, in increment
    raise MaxRetryError(_pool, url, error or ResponseError(cause))
urllib3.exceptions.MaxRetryError: HTTPSConnectionPool(host='api.wandb.ai', port=443): Max retries exceeded with url: /graphql (Caused by ConnectTimeoutError(<urllib3.connection.HTTPSConnection object at 0x7f950ba072e0>, 'Connection to api.wandb.ai timed out. (connect timeout=20)'))

During handling of the above exception, another exception occurred:

Traceback (most recent call last):
  File "/home/wangc/anaconda3/envs/test1/lib/python3.8/site-packages/wandb/sdk/lib/retry.py", line 131, in __call__
    result = self._call_fn(*args, **kwargs)
  File "/home/wangc/anaconda3/envs/test1/lib/python3.8/site-packages/wandb/sdk/internal/internal_api.py", line 369, in execute
    return self.client.execute(*args, **kwargs)  # type: ignore
  File "/home/wangc/anaconda3/envs/test1/lib/python3.8/site-packages/wandb/vendor/gql-0.2.0/wandb_gql/client.py", line 52, in execute
    result = self._get_result(document, *args, **kwargs)
  File "/home/wangc/anaconda3/envs/test1/lib/python3.8/site-packages/wandb/vendor/gql-0.2.0/wandb_gql/client.py", line 60, in _get_result
    return self.transport.execute(document, *args, **kwargs)
  File "/home/wangc/anaconda3/envs/test1/lib/python3.8/site-packages/wandb/sdk/lib/gql_request.py", line 58, in execute
    request = self.session.post(self.url, **post_args)
  File "/home/wangc/anaconda3/envs/test1/lib/python3.8/site-packages/requests/sessions.py", line 635, in post
    return self.request("POST", url, data=data, json=json, **kwargs)
  File "/home/wangc/anaconda3/envs/test1/lib/python3.8/site-packages/requests/sessions.py", line 587, in request
    resp = self.send(prep, **send_kwargs)
  File "/home/wangc/anaconda3/envs/test1/lib/python3.8/site-packages/requests/sessions.py", line 701, in send
    r = adapter.send(request, **kwargs)
  File "/home/wangc/anaconda3/envs/test1/lib/python3.8/site-packages/requests/adapters.py", line 553, in send
    raise ConnectTimeout(e, request=request)
requests.exceptions.ConnectTimeout: HTTPSConnectionPool(host='api.wandb.ai', port=443): Max retries exceeded with url: /graphql (Caused by ConnectTimeoutError(<urllib3.connection.HTTPSConnection object at 0x7f950ba072e0>, 'Connection to api.wandb.ai timed out. (connect timeout=20)'))
2024-12-21 13:10:12,861 ERROR   MainThread:3645908 [wandb_init.py:init():774] encountered error: Run initialization has timed out after 90.0 sec. 
Please refer to the documentation for additional information: https://docs.wandb.ai/guides/track/tracking-faq#initstarterror-error-communicating-with-wandb-process-
2024-12-21 13:10:13,702 ERROR   MainThread:3645908 [wandb_init.py:init():1199] Run initialization has timed out after 90.0 sec. 
Please refer to the documentation for additional information: https://docs.wandb.ai/guides/track/tracking-faq#initstarterror-error-communicating-with-wandb-process-
Traceback (most recent call last):
  File "/home/wangc/anaconda3/envs/test1/lib/python3.8/site-packages/wandb/sdk/wandb_init.py", line 1181, in init
    run = wi.init()
  File "/home/wangc/anaconda3/envs/test1/lib/python3.8/site-packages/wandb/sdk/wandb_init.py", line 780, in init
    raise error
wandb.errors.CommError: Run initialization has timed out after 90.0 sec. 
Please refer to the documentation for additional information: https://docs.wandb.ai/guides/track/tracking-faq#initstarterror-error-communicating-with-wandb-process-
2024-12-21 13:10:14,715 WARNING MsgRouterThr:3645908 [router.py:message_loop():77] message_loop has been closed
